Workbook

Sheet Somme_Total_Heures_Indispo
A3: Étiquettes de lignes | B3: Somme de Duree_Cumulee_Panne_Heure
A4: Bas-Uele | B4: 6.3319444
A5: Equateur | B5: 4.2861111
A6: Haut-Katanga | B6: 7.0847222
A7: Haut-Lomami | B7: 6.4895833
A8: Haut-Uele | B8: 2.6465278
A9: Ituri | B9: 6.2458333
A10: Kasai | B10: 4.8013889
A11: Kasai-Central | B11: 4.9868056
A12: Kasai-Oriental | B12: 5.1277778
A13: Kinshasa | B13: 3.9659722
A14: Kongo-Central | B14: 3.7333333
A15: Kwango | B15: 6.5638889
... A30: Total général | B30: 126.12292

Sheet Sous-categorisation
A3: Étiquettes de lignes | B3: Somme de Duree_Cumulee_Panne_Heure
A4: Bas-Uele | B4: 6.3319444
A5: Ericsson | B5: 0.83958333
A6: Huawei | B6: 0.925
A7: Nokia | B7: 2.0965278
A8: ZTE | B8: 2.4708333
A9: Equateur | B9: 4.2861111
A10: Ericsson | B10: 0.44791667
A11: Huawei | B11: 1.4513889
A12: Nokia | B12: 0.49930556
A13: ZTE | B13: 1.8875
A14: Haut-Katanga | B14: 7.0847222
A15: Ericsson | B15: 2.0861111
... A134: Total général | B134: 126.12292

Sheet Moyenne Nbr abonnes impact
A3: Étiquettes de lignes | B3: Nombre de Statut_Resolution | C3: moyenne
A4: Bas-Uele
A5: En Cours | B5: 14 | C5: 0.53846154
A6: Non Résolu | B6: 9 | C6: 0.34615385
A7: Equateur
A8: En Cours | B8: 8 | C8: 0.30769231
A9: Non Résolu | B9: 7 | C9: 0.26923077
A10: Haut-Katanga
A11: En Cours | B11: 9 | C11: 0.34615385
A12: Non Résolu | B12: 17 | C12: 0.65384615
A13: Haut-Lomami
A14: En Cours | B14: 6 | C14: 0.23076923
A15: Non Résolu | B15: 7 | C15: 0.26923077
A16: Haut-Uele
A17: En Cours | B17: 6 | C17: 0.23076923
A18: Non Résolu | B18: 6 | C18: 0.23076923
A19: Ituri
A20: En Cours | B20: 10 | C20: 0.38461538
A21: Non Résolu | B21: 13 | C21: 0.5
A22: Kasai
A23: En Cours | B23: 8 | C23: 0.30769231
A24: Non Résolu | B24: 9 | C24: 0.34615385
A25: Kasai-Central
A26: En Cours | B26: 11 | C26: 0.42307692
A27: Non Résolu | B27: 4 | C27: 0.15384615
A28: Kasai-Oriental
A29: En Cours | B29: 10 | C29: 0.38461538
A30: Non Résolu | B30: 8 | C30: 0.30769231
A31: Kinshasa
A32: En Cours | B32: 11 | C32: 0.42307692
A33: Non Résolu | B33: 9 | C33: 0.34615385
A34: Kongo-Central
A35: En Cours | B35: 8 | C35: 0.30769231
A36: Non Résolu | B36: 8 | C36: 0.30769231
A37: Kwango
A38: En Cours | B38: 5 | C38: 0.19230769
A39: Non Résolu | B39: 16 | C39: 0.61538462
A40: Kwilu
A41: En Cours | B41: 16 | C41: 0.61538462
A42: Non Résolu | B42: 9 | C42: 0.34615385
...

Sheet Total remise ou perte
A3: Étiquettes de lignes | B3: Somme de Montant_Remise
A4: Bas-Uele | B4: 556.3755
A5: Equateur | B5: 378.628
A6: Haut-Katanga | B6: 519.1125
A7: Haut-Lomami | B7: 459.3475
A8: Haut-Uele | B8: 201.0995
A9: Ituri | B9: 558.3065
A10: Kasai | B10: 486.8765
A11: Kasai-Central | B11: 550.498
A12: Kasai-Oriental | B12: 369.825
A13: Kinshasa | B13: 299.177
A14: Kongo-Central | B14: 269.568
A15: Kwango | B15: 598.7815
... A29: Tshuapa | B29: 451.1925
A30: (vide)
A31: Total général | B31: 10883.901

Sheet Master_Final
A1: Source.Name | B1: ID_Client | C1: Province_Client | D1: Cell_ID | E1: Technologie | F1: Equipementier | G1: Statut_Resolution | H1: Anciennete_Mois | I1: Anciennete_An | J1: Type_Abonnés | K1: Type_Forfait | L1: Duree_Cumulee_Panne_Min | M1: Duree_Cumulee_Panne_Heure | N1: Facture_Mensuelle | O1: Remise | P1: Montant_Remise | Q1: Plaintes_Service_Client
A2: Clients_Churn_Part_01.xlsx | B2: CLI-01147 | C2: Ituri | D2: =VLOOKUP(Clients_chun_clean[[#This Row],[Province_Client]],Master_Logs_reseau_registre!B2:F1073,2,0) -> ANT-0037 | E2: 3G | F2: Nokia | G2: Résolu | H2: 29 | I2: 2 | J2: B2C | K2: Premium 5G 150Go | L2: 214 | M2: 0.14861111 | N2: 74.7 | O2: =IF(AND(Clients_chun_clean[[#This Row],[Duree_Cumulee_Panne_Heure]]>TIME(12,0,0),Clients_chun_clean[[#This Row],[Anciennete_An]]>5),0.7,IF(OR(AND(Clients_chun_clean[[#This Row],[Duree_Cumulee_Panne_Heure]]>=TIME(4,0,0),Clients_chun_clean[[#This Row],[Duree_Cumulee_Panne_Heure]]<=TIME(12,0,0)),AND(Clients_chun_clean[[#This Row],[Anciennete_An]]<5,Clients_chun_clean[[#This Row],[Type_Forfait]]="Premium 5G 150Go")),0.45,IF(Clients_chun_clean[[#This Row],[Type_Abonnés]]="B2B",0.1,0))) -> 0.45 | P2: =Clients_chun_clean[[#This Row],[Facture_Mensuelle]]*Clients_chun_clean[[#This Row],[Remise]] -> 33.615 | Q2: 3
A3: Clients_Churn_Part_01.xlsx | B3: CLI-00894 | C3: Tshuapa | D3: =VLOOKUP(Clients_chun_clean[[#This Row],[Province_Client]],Master_Logs_reseau_registre!B3:F1074,2,0) -> ANT-0271 | E3: 5G | F3: Ericsson | G3: Non Résolu | H3: 63 | I3: 5 | J3: B2B | K3: Pro Monde | L3: 205 | M3: 0.14236111 | N3: 89.19 | O3: =IF(AND(Clients_chun_clean[[#This Row],[Duree_Cumulee_Panne_Heure]]>TIME(12,0,0),Clients_chun_clean[[#This Row],[Anciennete_An]]>5),0.7,IF(OR(AND(Clients_chun_clean[[#This Row],[Duree_Cumulee_Panne_Heure]]>=TIME(4,0,0),Clients_chun_clean[[#This Row],[Duree_Cumulee_Panne_Heure]]<=TIME(12,0,0)),AND(Clients_chun_clean[[#This Row],[Anciennete_An]]<5,Clients_chun_clean[[#This Row],[Type_Forfait]]="Premium 5G 150Go")),0.45,IF(Clients_chun_clean[[#This Row],[Type_Abonnés]]="B2B",0.1,0))) -> 0.1 | P3: =Clients_chun_clean[[#This Row],[Facture_Mensuelle]]*Clients_chun_clean[[#This Row],[Remise]] -> 8.919 | Q3: 0
A4: Clients_Churn_Part_01.xlsx | B4: CLI-00865 | C4: Mongala | D4: =VLOOKUP(Clients_chun_clean[[#This Row],[Province_Client]],Master_Logs_reseau_registre!B4:F1075,2,0) -> ANT-0855 | E4: 5G | F4: Ericsson | G4: Non Résolu | H4: 34 | I4: 2 | J4: B2B | K4: Pro Monde | L4: 453 | M4: 0.31458333 | N4: 56.84 | O4: =IF(AND(Clients_chun_clean[[#This Row],[Duree_Cumulee_Panne_Heure]]>TIME(12,0,0),Clients_chun_clean[[#This Row],[Anciennete_An]]>5),0.7,IF(OR(AND(Clients_chun_clean[[#This Row],[Duree_Cumulee_Panne_Heure]]>=TIME(4,0,0),Clients_chun_clean[[#This Row],[Duree_Cumulee_Panne_Heure]]<=TIME(12,0,0)),AND(Clients_chun_clean[[#This Row],[Anciennete_An]]<5,Clients_chun_clean[[#This Row],[Type_Forfait]]="Premium 5G 150Go")),0.45,IF(Clients_chun_clean[[#This Row],[Type_Abonnés]]="B2B",0.1,0))) -> 0.45 | P4: =Clients_chun_clean[[#This Row],[Facture_Mensuelle]]*Clients_chun_clean[[#This Row],[Remise]] -> 25.578 | Q4: 0
A5: Clients_Churn_Part_01.xlsx | B5: CLI-01325 | C5: Haut-Lomami | D5: =VLOOKUP(Clients_chun_clean[[#This Row],[Province_Client]],Master_Logs_reseau_registre!B5:F1076,2,0) -> ANT-0371 | E5: 4G | F5: Huawei | G5: Résolu | H5: 44 | I5: 3 | J5: B2C | K5: Bloqué 5Go | L5: 348 | M5: 0.24166667 | N5: 58.67 | O5: =IF(AND(Clients_chun_clean[[#This Row],[Duree_Cumulee_Panne_Heure]]>TIME(12,0,0),Clients_chun_clean[[#This Row],[Anciennete_An]]>5),0.7,IF(OR(AND(Clients_chun_clean[[#This Row],[Duree_Cumulee_Panne_Heure]]>=TIME(4,0,0),Clients_chun_clean[[#This Row],[Duree_Cumulee_Panne_Heure]]<=TIME(12,0,0)),AND(Clients_chun_clean[[#This Row],[Anciennete_An]]<5,Clients_chun_clean[[#This Row],[Type_Forfait]]="Premium 5G 150Go")),0.45,IF(Clients_chun_clean[[#This Row],[Type_Abonnés]]="B2B",0.1,0))) -> 0.45 | P5: =Clients_chun_clean[[#This Row],[Facture_Mensuelle]]*Clients_chun_clean[[#This Row],[Remise]] -> 26.4015 | Q5: 0
A6: Clients_Churn_Part_01.xlsx | B6: CLI-01855 | C6: Sud-Kivu | D6: =VLOOKUP(Clients_chun_clean[[#This Row],[Province_Client]],Master_Logs_reseau_registre!B6:F1077,2,0) -> ANT-0852 | E6: 3G | F6: Nokia | G6: En Cours | H6: 101 | I6: 8 | J6: B2C | K6: Illimité 50Go | L6: 358 | M6: 0.24861111 | N6: 29.24 | O6: =IF(AND(Clients_chun_clean[[#This Row],[Duree_Cumulee_Panne_Heure]]>TIME(12,0,0),Clients_chun_clean[[#This Row],[Anciennete_An]]>5),0.7,IF(OR(AND(Clients_chun_clean[[#This Row],[Duree_Cumulee_Panne_Heure]]>=TIME(4,0,0),Clients_chun_clean[[#This Row],[Duree_Cumulee_Panne_Heure]]<=TIME(12,0,0)),AND(Clients_chun_clean[[#This Row],[Anciennete_An]]<5,Clients_chun_clean[[#This Row],[Type_Forfait]]="Premium 5G 150Go")),0.45,IF(Clients_chun_clean[[#This Row],[Type_Abonnés]]="B2B",0.1,0))) -> 0.45 | P6: =Clients_chun_clean[[#This Row],[Facture_Mensuelle]]*Clients_chun_clean[[#This Row],[Remise]] -> 13.158 | Q6: 3
A7: Clients_Churn_Part_01.xlsx | B7: CLI-00076 | C7: Haut-Katanga | D7: =VLOOKUP(Clients_chun_clean[[#This Row],[Province_Client]],Master_Logs_reseau_registre!B7:F1078,2,0) -> ANT-0624 | E7: 3G | F7: Nokia | G7: En Cours | H7: 46 | I7: 3 | J7: B2C | K7: Premium 5G 150Go | L7: 283 | M7: 0.19652778 | N7: 56.05 | O7: =IF(AND(Clients_chun_clean[[#This Row],[Duree_Cumulee_Panne_Heure]]>TIME(12,0,0),Clients_chun_clean[[#This Row],[Anciennete_An]]>5),0.7,IF(OR(AND(Clients_chun_clean[[#This Row],[Duree_Cumulee_Panne_Heure]]>=TIME(4,0,0),Clients_chun_clean[[#This Row],[Duree_Cumulee_Panne_Heure]]<=TIME(12,0,0)),AND(Clients_chun_clean[[#This Row],[Anciennete_An]]<5,Clients_chun_clean[[#This Row],[Type_Forfait]]="Premium 5G 150Go")),0.45,IF(Clients_chun_clean[[#This Row],[Type_Abonnés]]="B2B",0.1,0))) -> 0.45 | P7: =Clients_chun_clean[[#This Row],[Facture_Mensuelle]]*Clients_chun_clean[[#This Row],[Remise]] -> 25.2225 | Q7: 1
A8: Clients_Churn_Part_01.xlsx | B8: CLI-00414 | C8: Bas-Uele | D8: =VLOOKUP(Clients_chun_clean[[#This Row],[Province_Client]],Master_Logs_reseau_registre!B8:F1079,2,0) -> ANT-0566 | E8: 3G | F8: Nokia | G8: En Cours | H8: 99 | I8: 8 | J8: B2C | K8: Premium 5G 150Go | L8: 447 | M8: 0.31041667 | N8: 38.1 | O8: =IF(AND(Clients_chun_clean[[#This Row],[Duree_Cumulee_Panne_Heure]]>TIME(12,0,0),Clients_chun_clean[[#This Row],[Anciennete_An]]>5),0.7,IF(OR(AND(Clients_chun_clean[[#This Row],[Duree_Cumulee_Panne_Heure]]>=TIME(4,0,0),Clients_chun_clean[[#This Row],[Duree_Cumulee_Panne_Heure]]<=TIME(12,0,0)),AND(Clients_chun_clean[[#This Row],[Anciennete_An]]<5,Clients_chun_clean[[#This Row],[Type_Forfait]]="Premium 5G 150Go")),0.45,IF(Clients_chun_clean[[#This Row],[Type_Abonnés]]="B2B",0.1,0))) -> 0.45 | P8: =Clients_chun_clean[[#This Row],[Facture_Mensuelle]]*Clients_chun_clean[[#This Row],[Remise]] -> 17.145 | Q8: 3
A9: Clients_Churn_Part_01.xlsx | B9: CLI-00327 | C9: Haut-Katanga | D9: =VLOOKUP(Clients_chun_clean[[#This Row],[Province_Client]],Master_Logs_reseau_registre!B9:F1080,2,0) -> ANT-0624 | E9: 3G | F9: Nokia | G9: En Cours | H9: 6 | I9: 0 | J9: B2C | K9: Illimité 50Go | L9: 155 | M9: 0.10763889 | N9: 40.66 | O9: =IF(AND(Clients_chun_clean[[#This Row],[Duree_Cumulee_Panne_Heure]]>TIME(12,0,0),Clients_chun_clean[[#This Row],[Anciennete_An]]>5),0.7,IF(OR(AND(Clients_chun_clean[[#This Row],[Duree_Cumulee_Panne_Heure]]>=TIME(4,0,0),Clients_chun_clean[[#This Row],[Duree_Cumulee_Panne_Heure]]<=TIME(12,0,0)),AND(Clients_chun_clean[[#This Row],[Anciennete_An]]<5,Clients_chun_clean[[#This Row],[Type_Forfait]]="Premium 5G 150Go")),0.45,IF(Clients_chun_clean[[#This Row],[Type_Abonnés]]="B2B",0.1,0))) -> 0 | P9: =Clients_chun_clean[[#This Row],[Facture_Mensuelle]]*Clients_chun_clean[[#This Row],[Remise]] -> 0 | Q9: 1
A10: Clients_Churn_Part_01.xlsx | B10: CLI-00559 | C10: Kasai | D10: =VLOOKUP(Clients_chun_clean[[#This Row],[Province_Client]],Master_Logs_reseau_registre!B10:F1081,2,0) -> ANT-0332 | E10: 4G | F10: Huawei | G10: Résolu | H10: 99 | I10: 8 | J10: B2C | K10: Bloqué 5Go | L10: 369 | M10: 0.25625 | N10: 67.21 | O10: =IF(AND(Clients_chun_clean[[#This Row],[Duree_Cumulee_Panne_Heure]]>TIME(12,0,0),Clients_chun_clean[[#This Row],[Anciennete_An]]>5),0.7,IF(OR(AND(Clients_chun_clean[[#This Row],[Duree_Cumulee_Panne_Heure]]>=TIME(4,0,0),Clients_chun_clean[[#This Row],[Duree_Cumulee_Panne_Heure]]<=TIME(12,0,0)),AND(Clients_chun_clean[[#This Row],[Anciennete_An]]<5,Clients_chun_clean[[#This Row],[Type_Forfait]]="Premium 5G 150Go")),0.45,IF(Clients_chun_clean[[#This Row],[Type_Abonnés]]="B2B",0.1,0))) -> 0.45 | P10: =Clients_chun_clean[[#This Row],[Facture_Mensuelle]]*Clients_chun_clean[[#This Row],[Remise]] -> 30.2445 | Q10: 3
A11: Clients_Churn_Part_01.xlsx | B11: CLI-00280 | C11: Sud-Ubangi | D11: =VLOOKUP(Clients_chun_clean[[#This Row],[Province_Client]],Master_Logs_reseau_registre!B11:F1082,2,0) -> ANT-0166 | E11: 5G | F11: Ericsson | G11: Non Résolu | H11: 113 | I11: 9 | J11: B2C | K11: Illimité 50Go | L11: 380 | M11: 0.26388889 | N11: 12.11 | O11: =IF(AND(Clients_chun_clean[[#This Row],[Duree_Cumulee_Panne_Heure]]>TIME(12,0,0),Clients_chun_clean[[#This Row],[Anciennete_An]]>5),0.7,IF(OR(AND(Clients_chun_clean[[#This Row],[Duree_Cumulee_Panne_Heure]]>=TIME(4,0,0),Clients_chun_clean[[#This Row],[Duree_Cumulee_Panne_Heure]]<=TIME(12,0,0)),AND(Clients_chun_clean[[#This Row],[Anciennete_An]]<5,Clients_chun_clean[[#This Row],[Type_Forfait]]="Premium 5G 150Go")),0.45,IF(Clients_chun_clean[[#This Row],[Type_Abonnés]]="B2B",0.1,0))) -> 0.45 | P11: =Clients_chun_clean[[#This Row],[Facture_Mensuelle]]*Clients_chun_clean[[#This Row],[Remise]] -> 5.4495 | Q11: 0
A12: Clients_Churn_Part_01.xlsx | B12: CLI-00060 | C12: Kasai-Central | D12: =VLOOKUP(Clients_chun_clean[[#This Row],[Province_Client]],Master_Logs_reseau_registre!B12:F1083,2,0) -> ANT-0379 | E12: 4G | F12: Huawei | G12: Résolu | H12: 72 | I12: 6 | J12: B2B | K12: Pro Monde | L12: 160 | M12: 0.11111111 | N12: 90.13 | O12: =IF(AND(Clients_chun_clean[[#This Row],[Duree_Cumulee_Panne_Heure]]>TIME(12,0,0),Clients_chun_clean[[#This Row],[Anciennete_An]]>5),0.7,IF(OR(AND(Clients_chun_clean[[#This Row],[Duree_Cumulee_Panne_Heure]]>=TIME(4,0,0),Clients_chun_clean[[#This Row],[Duree_Cumulee_Panne_Heure]]<=TIME(12,0,0)),AND(Clients_chun_clean[[#This Row],[Anciennete_An]]<5,Clients_chun_clean[[#This Row],[Type_Forfait]]="Premium 5G 150Go")),0.45,IF(Clients_chun_clean[[#This Row],[Type_Abonnés]]="B2B",0.1,0))) -> 0.1 | P12: =Clients_chun_clean[[#This Row],[Facture_Mensuelle]]*Clients_chun_clean[[#This Row],[Remise]] -> 9.013 | Q12: 2
A13: Clients_Churn_Part_01.xlsx | B13: CLI-00530 | C13: Sankuru | D13: =VLOOKUP(Clients_chun_clean[[#This Row],[Province_Client]],Master_Logs_reseau_registre!B13:F1084,2,0) -> ANT-0760 | E13: 4G | F13: Huawei | G13: Résolu | H13: 35 | I13: 2 | J13: B2B | K13: Pro Monde | L13: 465 | M13: 0.32291667 | N13: 58.59 | O13: =IF(AND(Clients_chun_clean[[#This Row],[Duree_Cumulee_Panne_Heure]]>TIME(12,0,0),Clients_chun_clean[[#This Row],[Anciennete_An]]>5),0.7,IF(OR(AND(Clients_chun_clean[[#This Row],[Duree_Cumulee_Panne_Heure]]>=TIME(4,0,0),Clients_chun_clean[[#This Row],[Duree_Cumulee_Panne_Heure]]<=TIME(12,0,0)),AND(Clients_chun_clean[[#This Row],[Anciennete_An]]<5,Clients_chun_clean[[#This Row],[Type_Forfait]]="Premium 5G 150Go")),0.45,IF(Clients_chun_clean[[#This Row],[Type_Abonnés]]="B2B",0.1,0))) -> 0.45 | P13: =Clients_chun_clean[[#This Row],[Facture_Mensuelle]]*Clients_chun_clean[[#This Row],[Remise]] -> 26.3655 | Q13: 5
... A749: Clients_Churn_Part_15.xlsx | B749: CLI-00800 | C749: Nord-Kivu | D749: =VLOOKUP(Clients_chun_clean[[#This Row],[Province_Client]],Master_Logs_reseau_registre!B749:F1820,2,0) -> ANT-0045 | E749: 5G | F749: ZTE | G749: Résolu | H749: 4 | I749: 0 | J749: B2C | K749: Bloqué 5Go | L749: 21 | M749: 0.014583333 | N749: 45.8 | O749: =IF(AND(Clients_chun_clean[[#This Row],[Duree_Cumulee_Panne_Heure]]>TIME(12,0,0),Clients_chun_clean[[#This Row],[Anciennete_An]]>5),0.7,IF(OR(AND(Clients_chun_clean[[#This Row],[Duree_Cumulee_Panne_Heure]]>=TIME(4,0,0),Clients_chun_clean[[#This Row],[Duree_Cumulee_Panne_Heure]]<=TIME(12,0,0)),AND(Clients_chun_clean[[#This Row],[Anciennete_An]]<5,Clients_chun_clean[[#This Row],[Type_Forfait]]="Premium 5G 150Go")),0.45,IF(Clients_chun_clean[[#This Row],[Type_Abonnés]]="B2B",0.1,0))) -> 0 | P749: =Clients_chun_clean[[#This Row],[Facture_Mensuelle]]*Clients_chun_clean[[#This Row],[Remise]] -> 0 | Q749: 1

Sheet Master_Logs_reseau_registre
A1: Source.Name | B1: Province_RDC | C1: Cell_ID | D1: Technologie | E1: Equipementier | F1: Statut_Resolution | G1: Date_Panne | H1: Heure_Panne | I1: Latitude | J1: Longitude | K1: Duree_Panne_Min
A2: Logs_Reseau_Part_01.xlsx | B2: Tanganyika | C2: ANT-0465 | D2: 4G | E2: Nokia | F2: Résolu | G2: 45203 | H2: 0.032638889 | I2: -11.144149 | J2: 27.244659 | K2: 73
A3: Logs_Reseau_Part_01.xlsx | B3: Pas de correspondance | C3: ANT-0004 | D3: Pas de correspondance | E3: Pas de correspondance | F3: Résolu | G3: 45208 | H3: 0.30138889 | I3: Pas de correspondance | J3: Pas de correspondance | K3: 38
A4: Logs_Reseau_Part_01.xlsx | B4: Pas de correspondance | C4: ANT-0977 | D4: Pas de correspondance | E4: Pas de correspondance | F4: Non Résolu | G4: 45204 | H4: 0.9625 | I4: Pas de correspondance | J4: Pas de correspondance | K4: 100
A5: Logs_Reseau_Part_01.xlsx | B5: Pas de correspondance | C5: ANT-0740 | D5: Pas de correspondance | E5: Pas de correspondance | F5: En Cours | G5: 45221 | H5: 0.99791667 | I5: Pas de correspondance | J5: Pas de correspondance | K5: 79
A6: Logs_Reseau_Part_01.xlsx | B6: Pas de correspondance | C6: ANT-0897 | D6: Pas de correspondance | E6: Pas de correspondance | F6: Résolu | G6: 45217 | H6: 0.10902778 | I6: Pas de correspondance | J6: Pas de correspondance | K6: 59
A7: Logs_Reseau_Part_01.xlsx | B7: Kongo-Central | C7: ANT-0737 | D7: 5G | E7: Ericsson | F7: Non Résolu | G7: 45213 | H7: 0.042361111 | I7: -2.821152 | J7: 20.651419 | K7: 119
A8: Logs_Reseau_Part_01.xlsx | B8: Kasai-Central | C8: ANT-0270 | D8: 5G | E8: Ericsson | F8: Résolu | G8: 45202 | H8: 0.25972222 | I8: -1.648264 | J8: 28.866144 | K8: 79
A9: Logs_Reseau_Part_01.xlsx | B9: Pas de correspondance | C9: ANT-0996 | D9: Pas de correspondance | E9: Pas de correspondance | F9: Résolu | G9: 45216 | H9: 0.79236111 | I9: Pas de correspondance | J9: Pas de correspondance | K9: 56
A10: Logs_Reseau_Part_01.xlsx | B10: Pas de correspondance | C10: ANT-0513 | D10: Pas de correspondance | E10: Pas de correspondance | F10: Non Résolu | G10: 45217 | H10: 0.28125 | I10: Pas de correspondance | J10: Pas de correspondance | K10: 51
A11: Logs_Reseau_Part_01.xlsx | B11: Pas de correspondance | C11: ANT-0781 | D11: Pas de correspondance | E11: Pas de correspondance | F11: En Cours | G11: 45220 | H11: 0.94027778 | I11: Pas de correspondance | J11: Pas de correspondance | K11: 33
A12: Logs_Reseau_Part_01.xlsx | B12: Kwango | C12: ANT-0183 | D12: 5G | E12: Ericsson | F12: Non Résolu | G12: 45213 | H12: 0.31111111 | I12: 4.831904 | J12: 20.733469 | K12: 22
A13: Logs_Reseau_Part_01.xlsx | B13: Lomami | C13: ANT-0520 | D13: 4G | E13: Huawei | F13: Résolu | G13: 45218 | H13: 0.36875 | I13: -8.422786 | J13: 16.781293 | K13: 70
A14: Logs_Reseau_Part_01.xlsx | B14: Nord-Ubangi | C14: ANT-0935 | D14: 5G | E14: ZTE | F14: En Cours | G14: 45227 | H14: 0.033333333 | I14: -10.375267 | J14: 17.993663 | K14: 68
A15: Logs_Reseau_Part_01.xlsx | B15: Pas de correspondance | C15: ANT-0892 | D15: Pas de correspondance | E15: Pas de correspondance | F15: Non Résolu | G15: 45213 | H15: 0.42847222 | I15: Pas de correspondance | J15: Pas de correspondance | K15: 101
A16: Logs_Reseau_Part_01.xlsx | B16: Lomami | C16: ANT-0641 | D16: 3G | E16: Nokia | F16: En Cours | G16: 45204 | H16: 0.28333333 | I16: -2.237157 | J16: 25.926188 | K16: 11
A17: Logs_Reseau_Part_01.xlsx | B17: Pas de correspondance | C17: ANT-0306 | D17: Pas de correspondance | E17: Pas de correspondance | F17: Résolu | G17: 45210 | H17: 0.12847222 | I17: Pas de correspondance | J17: Pas de correspondance | K17: 115
A18: Logs_Reseau_Part_01.xlsx | B18: Tanganyika | C18: ANT-0862 | D18: 3G | E18: ZTE | F18: Non Résolu | G18: 45212 | H18: 0.14027778 | I18: -9.470862 | J18: 29.234388 | K18: 19
A19: Logs_Reseau_Part_01.xlsx | B19: Pas de correspondance | C19: ANT-0655 | D19: Pas de correspondance | E19: Pas de correspondance | F19: Non Résolu | G19: 45227 | H19: 0.48472222 | I19: Pas de correspondance | J19: Pas de correspondance | K19: 24
A20: Logs_Reseau_Part_01.xlsx | B20: Lomami | C20: ANT-0520 | D20: 4G | E20: Huawei | F20: Non Résolu | G20: 45208 | H20: 0.073611111 | I20: -8.422786 | J20: 16.781293 | K20: 85
A21: Logs_Reseau_Part_01.xlsx | B21: Haut-Katanga | C21: ANT-0624 | D21: 3G | E21: Ericsson | F21: Résolu | G21: 45214 | H21: 0.71319444 | I21: 0.172153 | J21: 21.091376 | K21: 25
A22: Logs_Reseau_Part_01.xlsx | B22: Pas de correspondance | C22: ANT-0204 | D22: Pas de correspondance | E22: Pas de correspondance | F22: Non Résolu | G22: 45229 | H22: 0.50347222 | I22: Pas de correspondance | J22: Pas de correspondance | K22: 106
A23: Logs_Reseau_Part_01.xlsx | B23: Pas de correspondance | C23: ANT-0157 | D23: Pas de correspondance | E23: Pas de correspondance | F23: En Cours | G23: 45217 | H23: 0.41180556 | I23: Pas de correspondance | J23: Pas de correspondance | K23: 92
A24: Logs_Reseau_Part_01.xlsx | B24: Pas de correspondance | C24: ANT-0383 | D24: Pas de correspondance | E24: Pas de correspondance | F24: En Cours | G24: 45220 | H24: 0.83055556 | I24: Pas de correspondance | J24: Pas de correspondance | K24: 59
A25: Logs_Reseau_Part_01.xlsx | B25: Pas de correspondance | C25: ANT-0781 | D25: Pas de correspondance | E25: Pas de correspondance | F25: Non Résolu | G25: 45227 | H25: 0.48333333 | I25: Pas de correspondance | J25: Pas de correspondance | K25: 81
A26: Logs_Reseau_Part_01.xlsx | B26: Sud-Ubangi | C26: ANT-0166 | D26: 5G | E26: Ericsson | F26: Non Résolu | G26: 45206 | H26: 0.91944444 | I26: -10.56448 | J26: 19.792876 | K26: 13
A27: Logs_Reseau_Part_01.xlsx | B27: Nord-Kivu | C27: ANT-0553 | D27: 4G | E27: Ericsson | F27: En Cours | G27: 45201 | H27: 0.88472222 | I27: 4.628716 | J27: 19.407078 | K27: 54
A28: Logs_Reseau_Part_01.xlsx | B28: Pas de correspondance | C28: ANT-0977 | D28: Pas de correspondance | E28: Pas de correspondance | F28: En Cours | G28: 45224 | H28: 0.37847222 | I28: Pas de correspondance | J28: Pas de correspondance | K28: 53
A29: Logs_Reseau_Part_01.xlsx | B29: Pas de correspondance | C29: ANT-0798 | D29: Pas de correspondance | E29: Pas de correspondance | F29: Non Résolu | G29: 45227 | H29: 0.32986111 | I29: Pas de correspondance | J29: Pas de correspondance | K29: 81
A30: Logs_Reseau_Part_01.xlsx | B30: Tshopo | C30: ANT-0945 | D30: 3G | E30: ZTE | F30: En Cours | G30: 45203 | H30: 0.51180556 | I30: 0.235835 | J30: 24.889559 | K30: 64
A31: Logs_Reseau_Part_01.xlsx | B31: Pas de correspondance | C31: ANT-0544 | D31: Pas de correspondance | E31: Pas de correspondance | F31: Résolu | G31: 45214 | H31: 0.87013889 | I31: Pas de correspondance | J31: Pas de correspondance | K31: 72
A32: Logs_Reseau_Part_01.xlsx | B32: Tanganyika | C32: ANT-0941 | D32: 5G | E32: Ericsson | F32: Résolu | G32: 45211 | H32: 0.22430556 | I32: -2.466251 | J32: 18.007998 | K32: 37
A33: Logs_Reseau_Part_01.xlsx | B33: Nord-Ubangi | C33: ANT-0001 | D33: 4G | E33: ZTE | F33: Résolu | G33: 45211 | H33: 0.27916667 | I33: -8.143791 | J33: 28.946161 | K33: 75
A34: Logs_Reseau_Part_01.xlsx | B34: Tshopo | C34: ANT-0614 | D34: 3G | E34: Ericsson | F34: Résolu | G34: 45208 | H34: 0.95763889 | I34: -6.183785 | J34: 25.138759 | K34: 115
A35: Logs_Reseau_Part_01.xlsx | B35: Kasai | C35: ANT-0332 | D35: 4G | E35: Huawei | F35: En Cours | G35: 45221 | H35: 0.83611111 | I35: -4.978908 | J35: 28.506295 | K35: 6
A36: Logs_Reseau_Part_01.xlsx | B36: Pas de correspondance | C36: ANT-0501 | D36: Pas de correspondance | E36: Pas de correspondance | F36: Résolu | G36: 45219 | H36: 0.84027778 | I36: Pas de correspondance | J36: Pas de correspondance | K36: 92
A37: Logs_Reseau_Part_01.xlsx | B37: Kasai | C37: ANT-0020 | D37: 4G | E37: Huawei | F37: Non Résolu | G37: 45217 | H37: 0.96875 | I37: -10.059846 | J37: 14.375758 | K37: 97
A38: Logs_Reseau_Part_01.xlsx | B38: Pas de correspondance | C38: ANT-0115 | D38: Pas de correspondance | E38: Pas de correspondance | F38: Non Résolu | G38: 45205 | H38: 0.6 | I38: Pas de correspondance | J38: Pas de correspondance | K38: 19
A39: Logs_Reseau_Part_01.xlsx | B39: Kwilu | C39: ANT-0952 | D39: 4G | E39: Huawei | F39: Résolu | G39: 45208 | H39: 0.86388889 | I39: -0.774321 | J39: 18.628659 | K39: 92
A40: Logs_Reseau_Part_01.xlsx | B40: Pas de correspondance | C40: ANT-0372 | D40: Pas de correspondance | E40: Pas de correspondance | F40: Non Résolu | G40: 45217 | H40: 0.32152778 | I40: Pas de correspondance | J40: Pas de correspondance | K40: 118
...

Sheet Registre_maintenance_clean
A1: Source.Name | B1: ID_Antenne | C1: Province_RDC | D1: Latitude | E1: Longitude | F1: Technologie | G1: Equipementier
A2: Registre_Maintenance_Part_01.xlsx | B2: ANT-0622 | C2: Haut-Uele | D2: -3.003879 | E2: 23.633893 | F2: 5G | G2: Ericsson
A3: Registre_Maintenance_Part_01.xlsx | B3: ANT-0084 | C3: Kwilu | D3: 2.413557 | E3: 19.690682 | F3: 4G | G3: Huawei
A4: Registre_Maintenance_Part_01.xlsx | B4: ANT-0862 | C4: Tanganyika | D4: -9.470862 | E4: 29.234388 | F4: 3G | G4: ZTE
A5: Registre_Maintenance_Part_01.xlsx | B5: ANT-0288 | C5: Tshopo | D5: 1.400674 | E5: 13.503127 | F5: 5G | G5: ZTE
A6: Registre_Maintenance_Part_01.xlsx | B6: ANT-0880 | C6: Haut-Uele | D6: 0.293756 | E6: 18.528884 | F6: 5G | G6: ZTE
A7: Registre_Maintenance_Part_01.xlsx | B7: ANT-0847 | C7: Maniema | D7: -4.486234 | E7: 17.956159 | F7: 3G | G7: Huawei
A8: Registre_Maintenance_Part_01.xlsx | B8: ANT-0144 | C8: Tanganyika | D8: -12.824639 | E8: 24.407249 | F8: 5G | G8: Huawei
A9: Registre_Maintenance_Part_01.xlsx | B9: ANT-0913 | C9: Kinshasa | D9: -5.412628 | E9: 25.498236 | F9: 5G | G9: ZTE
A10: Registre_Maintenance_Part_01.xlsx | B10: ANT-0552 | C10: Kinshasa | D10: -10.57951 | E10: 23.502314 | F10: 4G | G10: ZTE
A11: Registre_Maintenance_Part_01.xlsx | B11: ANT-0202 | C11: Tshuapa | D11: 3.078867 | E11: 19.513651 | F11: 5G | G11: Huawei
A12: Registre_Maintenance_Part_01.xlsx | B12: ANT-0270 | C12: Kasai-Central | D12: -1.648264 | E12: 28.866144 | F12: 5G | G12: Ericsson
A13: Registre_Maintenance_Part_01.xlsx | B13: ANT-0752 | C13: Nord-Kivu | D13: -3.388313 | E13: 26.838507 | F13: 5G | G13: Nokia
... A499: Registre_Maintenance_Part_10.xlsx | B499: ANT-0090 | C499: Kasai-Central | D499: -7.337934 | E499: 28.404002 | F499: 3G | G499: Nokia

Sheet Feuil1
